Workbook

Sheet Summary
B2: Micron Technology (MU) — Three-Statement Model and DCF
B3: ="$ in millions except per share data · Active case: "&CHOOSE(Assumptions!C62,"Base","Bull","Bear") -> $ in millions except per share data · Active case: Base
B5: VALUATION SUMMARY | E5: INVESTMENT VIEW
B6: Valuation date | C6: =Assumptions!C36 -> 46279 | E6: ="Base case of "&TEXT(C21,"$#,##0")&" per share is "&TEXT(ABS(D21),"0%")&IF(D21<0," below"," above")&" the "&TEXT(Assumptions!C37,"$#,##0")&" share price (bull "&TEXT(C22,"$#,##0")&", bear "&TEXT(C23,"$#,##0")&")." -> Base case of $649 per share is 30% below the $924 share price (bull $939, bear $258).
B7: Current share price | C7: =Assumptions!C37 -> 924.03
B8: DCF implied value per share | C8: =DCF!C40 -> 649.12366
B9: Implied upside / (downside) | C9: =DCF!C42 -> -0.29750803 | E9: ="At "&TEXT(Assumptions!C37,"$#,##0")&", the stock is priced close to the bull case: FY2027 revenue near the ~$50B quarterly run rate Micron guided for Q4 FY2026, and a ~65% long run gross margin." -> At $924, the stock is priced close to the bull case: FY2027 revenue near the ~$50B quarterly run rate Micron guided for Q4 FY2026, and a ~65% long run gross margin.
B10: Enterprise value | C10: =DCF!C36 -> 692804.13
B11: Equity value | C11: =DCF!C38 -> 746492.2
B12: WACC | C12: =DCF!C28 -> 0.11325939 | E12: ="The base case has memory pricing easing as new industry capacity arrives in 2027–28, taking gross margin from "&TEXT(Statements!F11,"0%")&" in FY2026E to "&TEXT(Assumptions!K66,"0%")&" by FY2031E, near Micron's prior-cycle peak." -> The base case has memory pricing easing as new industry capacity arrives in 2027–28, taking gross margin from 80% in FY2026E to 60% by FY2031E, near Micron's prior-cycle peak.
B13: Beta | C13: =DCF!C20 -> 1.5068655
B14: Terminal growth rate | C14: =DCF!C31 -> 0.03
B15: Terminal value as % of EV | C15: =DCF!C43 -> 0.65442066 | E15: ="About $100B of committed revenue under Micron's strategic customer agreements should make the next downturn milder than past cycles,"&" but the bear case shows the value at risk. View: risk/reward is unfavorable at the current price. The question is how long AI driven margins last?" -> About $100B of committed revenue under Micron's strategic customer agreements should make the next downturn milder than past cycles, but the bear case shows the value at risk. View: risk/reward is unfavorable at the current price. The question is how long AI driven margins last?
B16: Implied terminal EV / EBITDA | C16: =DCF!C44 -> 7.3177778
B17: Net cash, FY2026E year-end | C17: =-DCF!C37 -> 53688.076
B19: SCENARIO VALUES PER SHARE
B20: Case | C20: Industry beta | D20: vs. price | E20: Regression beta | F20: vs. price | G20: Key assumptions
B21: Base | C21: 649.12 | D21: =C21/Assumptions!$C$37-1 -> -0.29751199 | E21: 500.17 | F21: =E21/Assumptions!$C$37-1 -> -0.45870805 | G21: FY27 revenue +18% (~$38B/quarter); gross margin eases to 60% by FY2031
B22: Bull | C22: 939.08 | D22: =C22/Assumptions!$C$37-1 -> 0.01628735 | E22: 714.79 | F22: =E22/Assumptions!$C$37-1 -> -0.22644286 | G22: FY27 revenue +35%, near the Q4 FY26 run rate; gross margin ~65% by FY2031
B23: Bear | C23: 258.4 | D23: =C23/Assumptions!$C$37-1 -> -0.7203554 | E23: 210.69 | F23: =E23/Assumptions!$C$37-1 -> -0.77198792 | G23: Flat FY27, then −15% and −25% in FY28–FY29; gross margin troughs at 42%
B25: OPERATING SUMMARY
B26: $ in millions | C26: FY2025A | D26: FY2026E | E26: FY2027E | F26: FY2028E | G26: FY2029E | H26: FY2030E | I26: FY2031E
B27: Revenue | C27: =Statements!E7 -> 37378 | D27: =Statements!F7 -> 128959 | E27: =Statements!G7 -> 152171.62 | F27: =Statements!H7 -> 161301.92 | G27: =Statements!I7 -> 145171.73 | H27: =Statements!J7 -> 137913.14 | I27: =Statements!K7 -> 146187.93
B28: Revenue growth | C28: =Statements!E8 -> 0.48851101 | D28: =Statements!F8 -> 2.4501311 | E28: =Statements!G8 -> 0.18 | F28: =Statements!H8 -> 0.06 | G28: =Statements!I8 -> -0.1 | H28: =Statements!J8 -> -0.05 | I28: =Statements!K8 -> 0.06
B29: Gross margin | C29: =Statements!E11 -> 0.39790786 | D29: =Statements!F11 -> 0.80224723 | E29: =Statements!G11 -> 0.82 | F29: =Statements!H11 -> 0.78 | G29: =Statements!I11 -> 0.68 | H29: =Statements!J11 -> 0.58 | I29: =Statements!K11 -> 0.6
B30: Operating margin | C30: =Statements!E16 -> 0.2613837 | D30: =Statements!F16 -> 0.75007561 | E30: =Statements!G16 -> 0.7677 | F30: =Statements!H16 -> 0.7277 | G30: =Statements!I16 -> 0.6236 | H30: =Statements!J16 -> 0.5145 | I30: =Statements!K16 -> 0.5375
B31: EBITDA | C31: =Statements!E18 -> 18122 | D31: =Statements!F18 -> 106091 | E31: =Statements!G18 -> 129590.35 | F31: =Statements!H18 -> 134672.51 | G31: =Statements!I18 -> 111133.84 | H31: =Statements!J18 -> 93182.552 | I31: =Statements!K18 -> 100408.83
B32: Net income | C32: =Statements!E26 -> 8539 | D32: =Statements!F26 -> 82419.75 | E32: =Statements!G26 -> 100579.75 | F32: =Statements!H26 -> 101042.38 | G32: =Statements!I26 -> 78253.403 | H32: =Statements!J26 -> 61635.257 | I32: =Statements!K26 -> 68104.31
B33: Diluted EPS | C33: =Statements!E28 -> 7.5902222 | D33: =Statements!F28 -> 71.669348 | E33: =Statements!G28 -> 93.033584 | F33: =Statements!H28 -> 100.23716 | G33: =Statements!I28 -> 83.181479 | H33: =Statements!J28 -> 69.997302 | I33: =Statements!K28 -> 83.431692
B34: Free cash flow | C34: =Statements!E81 -> 3673 | D34: =Statements!F81 -> 57752.276 | E34: =Statements!G81 -> 65575.568 | F34: =Statements!H81 -> 69677.426 | G34: =Statements!I81 -> 64309.054 | H34: =Statements!J81 -> 57840.198 | I34: =Statements!K81 -> 61732.639
B35: Net debt / (cash) | C35: =Statements!E53 -> 2637 | D35: =Statements!F53 -> -53688.076 | E35: =Statements!G53 -> -53688.076 | F35: =Statements!H53 -> -53688.076 | G35: =Statements!I53 -> -53688.076 | H35: =Statements!J53 -> -53688.076 | I35: =Statements!K53 -> -53688.076
B36: Diluted shares (millions) | C36: =Statements!E27 -> 1125 | D36: =Statements!F27 -> 1150 | E36: =Statements!G27 -> 1081.1122 | F36: =Statements!H27 -> 1008.0331 | G36: =Statements!I27 -> 940.75514 | H36: =Statements!J27 -> 880.5376 | I36: =Statements!K27 -> 816.28826

Sheet Assumptions
B2: Micron Technology (MU) — Model Assumptions
B3: Blue = hardcoded input · Black = formula · Green = link to another sheet · $ in millions except per-share data
B5: Fiscal Year | C5: FY2023A | D5: FY2024A | E5: FY2025A | F5: FY2026E | G5: FY2027E | H5: FY2028E | I5: FY2029E | J5: FY2030E | K5: FY2031E
B6: INCOME STATEMENT ASSUMPTIONS
B7: Revenue growth | D7: =Statements!D8 -> 0.61589447 | E7: =Statements!E8 -> 0.48851101 | F7: =Statements!F8 -> 2.4501311 | G7: =CHOOSE($C$62,G63,G64,G65) -> 0.18 | H7: =CHOOSE($C$62,H63,H64,H65) -> 0.06 | I7: =CHOOSE($C$62,I63,I64,I65) -> -0.1 | J7: =CHOOSE($C$62,J63,J64,J65) -> -0.05 | K7: =CHOOSE($C$62,K63,K64,K65) -> 0.06 | M7: FY2026E from FY26 Bridge; FY2027E+ from the active scenario (rows 63–65)
B8: Gross margin | C8: =Statements!C11 -> -0.091119691 | D8: =Statements!D11 -> 0.22352754 | E8: =Statements!E11 -> 0.39790786 | F8: =Statements!F11 -> 0.80224723 | G8: =CHOOSE($C$62,G66,G67,G68) -> 0.82 | H8: =CHOOSE($C$62,H66,H67,H68) -> 0.78 | I8: =CHOOSE($C$62,I66,I67,I68) -> 0.68 | J8: =CHOOSE($C$62,J66,J67,J68) -> 0.58 | K8: =CHOOSE($C$62,K66,K67,K68) -> 0.6 | M8: FY2026E from FY26 Bridge; FY2027E+ from the active scenario (rows 66–68)
B9: R&D as % of revenue | C9: =Statements!C12/Statements!C7 -> 0.2003861 | D9: =Statements!D12/Statements!D7 -> 0.13659352 | E9: =Statements!E12/Statements!E7 -> 0.10161057 | F9: =Statements!F12/Statements!F7 -> 0.039905564 | G9: 0.04 | H9: 0.04 | I9: 0.043 | J9: 0.05 | K9: 0.048 | M9: FY2026E ratios on rows 9–15 are calculated from the FY26 Bridge
B10: SG&A as % of revenue | C10: =Statements!C13/Statements!C7 -> 0.059202059 | D10: =Statements!D13/Statements!D7 -> 0.044960376 | E10: =Statements!E13/Statements!E7 -> 0.032238215 | F10: =Statements!F13/Statements!F7 -> 0.011816301 | G10: 0.012 | H10: 0.012 | I10: 0.013 | J10: 0.015 | K10: 0.014
B11: Other operating expense as % of revenue | C11: =Statements!C14/Statements!C7 -> 0.018983269 | D11: =Statements!D14/Statements!D7 -> -0.0099557963 | E11: =Statements!E14/Statements!E7 -> 0.0026753705 | F11: =Statements!F14/Statements!F7 -> 0.00044975535 | G11: 0.0003 | H11: 0.0003 | I11: 0.0004 | J11: 0.0005 | K11: 0.0005
B12: Tax rate | C12: =IF(Statements!C23>0,Statements!C24/Statements!C23,0) -> 0 | D12: =IF(Statements!D23>0,Statements!D24/Statements!D23,0) -> 0.36370968 | E12: =IF(Statements!E23>0,Statements!E24/Statements!E23,0) -> 0.11642842 | F12: =IF(Statements!F23>0,Statements!F24/Statements!F23,0) -> 0.14858505 | G12: 0.15 | H12: 0.15 | I12: 0.15 | J12: 0.15 | K12: 0.15
B13: Interest income yield | C13: =Statements!C20/SUM(Statements!C34:C35) -> 0.044499382 | D13: =Statements!D20/SUM(Statements!D34:D35) -> 0.057732184 | E13: =Statements!E20/SUM(Statements!E34:E35) -> 0.041541039 | F13: =Statements!F20/SUM(Statements!E34:E35) -> 0.060636516 | G13: 0.035 | H13: 0.035 | I13: 0.035 | J13: 0.035 | K13: 0.035 | M13: FY2026E ratio looks high because cash rose sharply during the year
B14: Interest expense rate | C14: =Statements!C21/Statements!C45 -> 0.029107277 | D14: =Statements!D21/Statements!D45 -> 0.04194969 | E14: =Statements!E21/Statements!E45 -> 0.032722782 | F14: =Statements!F21/AVERAGE(Statements!E45,Statements!F45) -> 0.010443864 | G14: 0.05 | H14: 0.05 | I14: 0.05 | J14: 0.05 | K14: 0.05
B15: Other income / (expense) as % of revenue | C15: =Statements!C22/Statements!C7 -> 0.00045045045 | D15: =Statements!D22/Statements!D7 -> -0.0012345187 | E15: =Statements!E22/Statements!E7 -> -0.0036117502 | F15: =Statements!F22/Statements!F7 -> -0.004334711 | G15: -0.002 | H15: -0.002 | I15: -0.002 | J15: -0.002 | K15: -0.002
B17: BALANCE SHEET AND CASH FLOW ASSUMPTIONS
B18: Receivable days (DSO, on revenue) | C18: =Statements!C36/Statements!C7*365 -> 57.380631 | D18: =Statements!D36/Statements!D7*365 -> 96.152085 | E18: =Statements!E36/Statements!E7*365 -> 90.473674 | F18: 80 | G18: 70 | H18: 65 | I18: 60 | J18: 55 | K18: 55 | M18: Days on a 365-day basis
B19: Inventory days (DIO, on COGS) | C19: =Statements!C37/Statements!C9*365 -> 180.54111 | D19: =Statements!D37/Statements!D9*365 -> 166.13883 | E19: =Statements!E37/Statements!E9*365 -> 135.50655 | F19: 122 | G19: 115 | H19: 110 | I19: 105 | J19: 105 | K19: 105 | M19: Days on a 365-day basis
B20: Payable days (DPO, on COGS) | C20: =Statements!C44/Statements!C9*365 -> 85.201109 | D20: =Statements!D44/Statements!D9*365 -> 136.63632 | E20: =Statements!E44/Statements!E9*365 -> 156.49345 | F20: 200 | G20: 180 | H20: 165 | I20: 150 | J20: 145 | K20: 145 | M20: Days on a 365-day basis
B21: Other current assets as % of revenue | C21: =Statements!C38/Statements!C7 -> 0.052767053 | D21: =Statements!D38/Statements!D7 -> 0.030902792 | E21: =Statements!E38/Statements!E7 -> 0.024452887 | F21: 0.01 | G21: 0.01 | H21: 0.01 | I21: 0.01 | J21: 0.01 | K21: 0.01
B22: Other current liabilities as % of revenue | C22: =Statements!C46/Statements!C7 -> 0.034041184 | D22: =Statements!D46/Statements!D7 -> 0.060451595 | E22: =Statements!E46/Statements!E7 -> 0.033308363 | F22: 0.026 | G22: 0.025 | H22: 0.025 | I22: 0.025 | J22: 0.025 | K22: 0.025
B23: Marketable securities as % of revenue | C23: =Statements!C35/Statements!C7 -> 0.11975547 | D23: =Statements!D35/Statements!D7 -> 0.084066744 | E23: =Statements!E35/Statements!E7 -> 0.061373 | F23: 0.04 | G23: 0.04 | H23: 0.04 | I23: 0.04 | J23: 0.04 | K23: 0.04
B24: Other long-term assets as % of revenue | C24: =Statements!C40/Statements!C7 -> 0.26763192 | D24: =Statements!D40/Statements!D7 -> 0.16877066 | E24: =Statements!E40/Statements!E7 -> 0.15340575 | F24: 0.054 | G24: 0.05 | H24: 0.05 | I24: 0.05 | J24: 0.05 | K24: 0.05
B25: Other long-term liabilities as % of revenue | C25: =Statements!C47/Statements!C7 -> 0.1490991 | D25: =Statements!D47/Statements!D7 -> 0.082473816 | E25: =Statements!E47/Statements!E7 -> 0.084595216 | F25: 0.068 | G25: 0.045 | H25: 0.04 | I25: 0.035 | J25: 0.03 | K25: 0.03
B26: D&A as % of beginning PP&E | D26: =Statements!D17/Statements!C39 -> 0.2051255 | E26: =Statements!E17/Statements!D39 -> 0.21011849 | F26: =Statements!F17/Statements!E39 -> 0.20094441 | G26: 0.2 | H26: 0.18 | I26: 0.16 | J26: 0.15 | K26: 0.14 | M26: FY2026E from FY26 Bridge
B27: Capital expenditures | C27: =-Statements!C67 -> 7676 | D27: =-Statements!D67 -> 8386 | E27: =-Statements!E67 -> 15857 | F27: ='FY26 Bridge'!E28 -> 29602 | G27: 45000 | H27: 50000 | I27: 40000 | J27: 30000 | K27: 28000 | M27: FY2026E ~$27B net of incentives per guidance; FY27 quarterly capex guided above Q4 FY26 (~$10B)
B28: Ending debt | C28: =Statements!C45 -> 13330 | D28: =Statements!D45 -> 13397 | E28: =Statements!E45 -> 14577 | F28: 5722 | G28: 5000 | H28: 4500 | I28: 4000 | J28: 3500 | K28: 3000 | M28: FY2026E = total debt at Q3 FY2026 (May 28, 2026)
B29: Stock-based compensation as % of revenue | C29: =Statements!C64/Statements!C7 -> 0.038352638 | D29: =Statements!D64/Statements!D7 -> 0.033172713 | E29: =Statements!E64/Statements!E7 -> 0.026004602 | F29: =Statements!F64/Statements!F7 -> 0.010220303 | G29: 0.007 | H29: 0.007 | I29: 0.007 | J29: 0.007 | K29: 0.007
B30: Government incentive proceeds | C30: =Statements!C68 -> 710 | D30: =Statements!D68 -> 315 | E30: =Statements!E68 -> 2005 | F30: ='FY26 Bridge'!E29 -> 2989 | G30: 0 | H30: 0 | I30: 0 | J30: 0 | K30: 0 | M30: Incentives reduce PP&E as well as adding cash
B31: Dividends paid | C31: =-Statements!C72 -> 504 | D31: =-Statements!D72 -> 513 | E31: =-Statements!E72 -> 522 | F31: ='FY26 Bridge'!E31 -> 606.2 | G31: 856 | H31: 1021 | I31: 1126 | J31: 1232 | K31: 1341
B32: Share repurchases | C32: =-Statements!C73 -> 425 | D32: =-Statements!D73 -> 300 | E32: =-Statements!E73 -> 0 | F32: ='FY26 Bridge'!E32 -> 650 | G32: =MAX(0,G55*Statements!G81-G31) -> 64719.568 | H32: =MAX(0,H55*Statements!H81-H31) -> 68656.426 | I32: =MAX(0,I55*Statements!I81-I31) -> 63183.054 | J32: =MAX(0,J55*Statements!J81-J31) -> 56608.198 | K32: =MAX(0,K55*Statements!K81-K31) -> 60391.639 | M32: FY2027E+: FCF × payout % (row 55) − dividends
B33: Diluted shares (millions) | C33: =Statements!C27 -> 1093 | D33: =Statements!D27 -> 1118 | E33: =Statements!E27 -> 1125 | F33: 1150 | G33: =F33-G32/G56+Statements!G64/G56 -> 1081.1122 | H33: =G33-H32/H56+Statements!H64/H56 -> 1008.0331 | I33: =H33-I32/I56+Statements!I64/I56 -> 940.75514 | J33: =I33-J32/J56+Statements!J64/J56 -> 880.5376 | K33: =J33-K32/K56+Statements!K64/K56 -> 816.28826 | M33: FY2026E per Q4 guidance; later years net buybacks and SBC issuance at row 56 price
B35: DCF AND MARKET ASSUMPTIONS
B36: Valuation date | C36: 46279 | D36: Latest market close used in the model
B37: Current share price | C37: 924.03 | D37: Closing price on 9/14/2026 (Yahoo Finance / Nasdaq)
B38: Risk-free rate | C38: 0.0499 | D38: 10-year U.S. Treasury yield at the 9/14/2026 close (Trading Economics; FRED series DGS10)
B39: Levered beta | C39: =CHOOSE(C48,C51,C52) -> 1.5068655 | D39: Selected in the beta build below (1 = industry bottom-up, 2 = regression)
B40: Equity risk premium | C40: 0.0423 | D40: Damodaran implied U.S. equity risk premium, start of 2026
B41: Pre-tax cost of debt | C41: 0.05 | D41: Assumption; debt is ~0.5% of capital, so WACC is barely sensitive to this
B42: Marginal tax rate | C42: 0.15 | D42: Close to the 9M FY2026 effective tax rate (14.8%)
B43: Terminal growth rate | C43: 0.03 | D43: Long-term growth after FY2031
B44: Net debt / (cash) | C44: =Statements!F53 -> -53688.076 | D44: FY2026E year-end net debt / (cash); FY2026 ended before the valuation date
...

Sheet FY26 Bridge
B2: Micron Technology (MU) — FY2026 Estimate Bridge
B3: FY2026E = nine months ended May 28, 2026 (reported) + Q4 FY2026 (company guidance where given; otherwise labeled as an estimate). $ in millions.
B5: Line item | C5: 9M FY2026A | D5: Q4 FY2026E | E5: FY2026E | F5: Basis for Q4 FY2026E
B6: INCOME STATEMENT
B7: Revenue | C7: 78959 | D7: 50000 | E7: =C7+D7 -> 128959 | F7: Guidance midpoint ($50.0B ± $1.0B)
B8: Gross margin % | C8: =C10/C7 -> 0.76567586 | D8: 0.86 | E8: =E10/E7 -> 0.80224723 | F8: Guidance (~86%)
B9: Cost of goods sold | C9: 18502 | D9: =D7*(1-D8) -> 7000 | E9: =C9+D9 -> 25502 | F9: Revenue × (1 − gross margin)
B10: Gross profit | C10: =C7-C9 -> 60457 | D10: =D7-D9 -> 43000 | E10: =E7-E9 -> 103457
B11: Total operating expenses (GAAP) | C11: =SUM(C12:C14) -> 4868 | D11: 1860 | E11: =SUM(E12:E14) -> 6728 | F11: Guidance (~$1.86B GAAP)
B12: Research and development | C12: 3737 | D12: =(D11-D14)*C39/(C39+C40) -> 1409.1817 | E12: =C12+D12 -> 5146.1817 | F12: Guided opex less other, split on the Q3 FY2026 R&D / SG&A mix
B13: Selling, general and administrative | C13: 1088 | D13: =D11-D12-D14 -> 435.81834 | E13: =C13+D13 -> 1523.8183 | F13: Remainder of guided opex
B14: Other operating expense / (income) | C14: 43 | D14: 15 | E14: =C14+D14 -> 58 | F14: Estimate: Q3 FY2026 level (not guided)
B15: Operating income | C15: =C10-C11 -> 55589 | D15: =D10-D11 -> 41140 | E15: =E10-E11 -> 96729
B16: Depreciation and amortization | C16: 6862 | D16: 2500 | E16: =C16+D16 -> 9362 | F16: Estimate (not guided): above the 9M average of ~$2.3B/quarter as new capacity ramps
B17: Interest income | C17: 509 | D17: 215 | E17: =C17+D17 -> 724 | F17: Estimate: Q3 FY2026 level
B18: Interest expense | C18: 106 | D18: 0 | E18: =C18+D18 -> 106 | F18: Estimate: Q3 FY2026 was nil after debt prepayments
B19: Other non-operating income / (expense) | C19: -559 | D19: 0 | E19: =C19+D19 -> -559 | F19: Estimate: 9M included losses on debt prepayments
B20: Income before taxes | C20: =C15+C17-C18+C19 -> 55433 | D20: =D15+D17-D18+D19 -> 41355 | E20: =E15+E17-E18+E19 -> 96788
B21: Effective tax rate | C21: =C22/C20 -> 0.14752945 | D21: 0.15 | E21: =E22/E20 -> 0.14858505 | F21: Estimate: in line with the 9M effective rate
B22: Income tax expense | C22: 8178 | D22: =D20*D21 -> 6203.25 | E22: =C22+D22 -> 14381.25
B23: Equity in income / (loss) of investees | C23: 13 | D23: 0 | E23: =C23+D23 -> 13 | F23: Estimate
B24: Net income | C24: =C20-C22+C23 -> 47268 | D24: =D20-D22+D23 -> 35151.75 | E24: =E20-E22+E23 -> 82419.75
B26: CASH FLOW ITEMS
B27: Stock-based compensation | C27: 954 | D27: 364 | E27: =C27+D27 -> 1318 | F27: Guidance reconciliation: $159M COGS + $138M R&D + $67M SG&A
B28: Capital expenditures (gross) | C28: 19602 | D28: 10000 | E28: =C28+D28 -> 29602 | F28: Guidance: ~$10B Q4 capex; assumes no Q4 government incentives
B29: Government incentive proceeds | C29: 2989 | D29: 0 | E29: =C29+D29 -> 2989 | F29: Assumed nil in Q4
B30: Capital expenditures, net of incentives | C30: =C28-C29 -> 16613 | D30: =D28-D29 -> 10000 | E30: =E28-E29 -> 26613 | F30: Check: guidance is ~$27B for FY2026
B31: Dividends paid | C31: 437 | D31: =D41*D42 -> 169.2 | E31: =C31+D31 -> 606.2 | F31: $0.15/share declared June 24, 2026 × Q3 basic share count
B32: Share repurchases (program) | C32: 650 | D32: 0 | E32: =C32+D32 -> 650 | F32: Q4 amount not yet reported (FY2026 results due September 30, 2026); assumed nil
B33: Other financing activities | C33: -179 | D33: 0 | E33: =C33+D33 -> -179 | F33: 9M = −$762M equity-award tax withholdings + $583M other
B34: Foreign exchange effect on cash | C34: 8 | D34: 0 | E34: =C34+D34 -> 8 | F34: Estimate
B36: REFERENCE INPUTS AND CHECKS
B37: Reported 9M FY2026 net income | C37: 47268
B38: Check: model 9M net income less reported (should be 0) | C38: =C24-C37 -> 0
B39: Q3 FY2026 research and development | C39: 1316
B40: Q3 FY2026 selling, general and administrative | C40: 407
B41: Quarterly dividend per share (declared June 24, 2026) | D41: 0.15
B42: Basic shares, Q3 FY2026 (millions) | D42: 1128
B43: Q4 FY2026 GAAP EPS guidance | D43: 30.73
B44: Q4 guidance share count (millions) | D44: =Assumptions!F33 -> 1150 | F44: Approx. 1.15B diluted shares per guidance
...

Sheet Statements
B2: Micron Technology (MU) — Three-Statement Model
B3: FY2023–FY2025 actuals · FY2026E = 9M actuals + Q4 guidance (FY26 Bridge tab) · FY2027E–FY2031E forecast · $ in millions except per-share data
B5: Fiscal Year | C5: FY2023A | D5: FY2024A | E5: FY2025A | F5: FY2026E | G5: FY2027E | H5: FY2028E | I5: FY2029E | J5: FY2030E | K5: FY2031E
B6: INCOME STATEMENT
B7: Revenue | C7: 15540 | D7: 25111 | E7: 37378 | F7: ='FY26 Bridge'!E7 -> 128959 | G7: =F7*(1+Assumptions!G$7) -> 152171.62 | H7: =G7*(1+Assumptions!H$7) -> 161301.92 | I7: =H7*(1+Assumptions!I$7) -> 145171.73 | J7: =I7*(1+Assumptions!J$7) -> 137913.14 | K7: =J7*(1+Assumptions!K$7) -> 146187.93
B8: Revenue growth | D8: =D7/C7-1 -> 0.61589447 | E8: =E7/D7-1 -> 0.48851101 | F8: =F7/E7-1 -> 2.4501311 | G8: =G7/F7-1 -> 0.18 | H8: =H7/G7-1 -> 0.06 | I8: =I7/H7-1 -> -0.1 | J8: =J7/I7-1 -> -0.05 | K8: =K7/J7-1 -> 0.06
B9: Cost of goods sold | C9: 16956 | D9: 19498 | E9: 22505 | F9: ='FY26 Bridge'!E9 -> 25502 | G9: =G7*(1-Assumptions!G$8) -> 27390.892 | H9: =H7*(1-Assumptions!H$8) -> 35486.422 | I9: =I7*(1-Assumptions!I$8) -> 46454.952 | J9: =J7*(1-Assumptions!J$8) -> 57923.518 | K9: =K7*(1-Assumptions!K$8) -> 58475.171
B10: Gross profit | C10: =C7-C9 -> -1416 | D10: =D7-D9 -> 5613 | E10: =E7-E9 -> 14873 | F10: =F7-F9 -> 103457 | G10: =G7-G9 -> 124780.73 | H10: =H7-H9 -> 125815.5 | I10: =I7-I9 -> 98716.773 | J10: =J7-J9 -> 79989.621 | K10: =K7-K9 -> 87712.757
B11: Gross margin | C11: =C10/C7 -> -0.091119691 | D11: =D10/D7 -> 0.22352754 | E11: =E10/E7 -> 0.39790786 | F11: =F10/F7 -> 0.80224723 | G11: =G10/G7 -> 0.82 | H11: =H10/H7 -> 0.78 | I11: =I10/I7 -> 0.68 | J11: =J10/J7 -> 0.58 | K11: =K10/K7 -> 0.6
B12: Research and development | C12: 3114 | D12: 3430 | E12: 3798 | F12: ='FY26 Bridge'!E12 -> 5146.1817 | G12: =G7*Assumptions!G$9 -> 6086.8648 | H12: =H7*Assumptions!H$9 -> 6452.0767 | I12: =I7*Assumptions!I$9 -> 6242.3842 | J12: =J7*Assumptions!J$9 -> 6895.657 | K12: =K7*Assumptions!K$9 -> 7017.0205
B13: Selling, general and administrative | C13: 920 | D13: 1129 | E13: 1205 | F13: ='FY26 Bridge'!E13 -> 1523.8183 | G13: =G7*Assumptions!G$10 -> 1826.0594 | H13: =H7*Assumptions!H$10 -> 1935.623 | I13: =I7*Assumptions!I$10 -> 1887.2324 | J13: =J7*Assumptions!J$10 -> 2068.6971 | K13: =K7*Assumptions!K$10 -> 2046.631
B14: Other operating expense / (income) | C14: 295 | D14: -250 | E14: 100 | F14: ='FY26 Bridge'!E14 -> 58 | G14: =G7*Assumptions!G$11 -> 45.651486 | H14: =H7*Assumptions!H$11 -> 48.390575 | I14: =I7*Assumptions!I$11 -> 58.06869 | J14: =J7*Assumptions!J$11 -> 68.95657 | K14: =K7*Assumptions!K$11 -> 73.093964
B15: Operating income / (loss) | C15: =C10-SUM(C12:C14) -> -5745 | D15: =D10-SUM(D12:D14) -> 1304 | E15: =E10-SUM(E12:E14) -> 9770 | F15: =F10-SUM(F12:F14) -> 96729 | G15: =G10-SUM(G12:G14) -> 116822.15 | H15: =H10-SUM(H12:H14) -> 117379.41 | I15: =I10-SUM(I12:I14) -> 90529.088 | J15: =J10-SUM(J12:J14) -> 70956.31 | K15: =K10-SUM(K12:K14) -> 78576.011
B16: Operating margin | C16: =C15/C7 -> -0.36969112 | D16: =D15/D7 -> 0.051929433 | E16: =E15/E7 -> 0.2613837 | F16: =F15/F7 -> 0.75007561 | G16: =G15/G7 -> 0.7677 | H16: =H15/H7 -> 0.7277 | I16: =I15/I7 -> 0.6236 | J16: =J15/J7 -> 0.5145 | K16: =K15/K7 -> 0.5375
B17: Depreciation and amortization | C17: 7756 | D17: 7780 | E17: 8352 | F17: ='FY26 Bridge'!E16 -> 9362 | G17: =F39*Assumptions!G$26 -> 12768.2 | H17: =G39*Assumptions!H$26 -> 17293.104 | I17: =H39*Assumptions!I$26 -> 20604.751 | J17: =I39*Assumptions!J$26 -> 22226.242 | K17: =J39*Assumptions!K$26 -> 21832.818
B18: EBITDA | C18: =C15+C17 -> 2011 | D18: =D15+D17 -> 9084 | E18: =E15+E17 -> 18122 | F18: =F15+F17 -> 106091 | G18: =G15+G17 -> 129590.35 | H18: =H15+H17 -> 134672.51 | I18: =I15+I17 -> 111133.84 | J18: =J15+J17 -> 93182.552 | K18: =K15+K17 -> 100408.83
B19: EBITDA margin | C19: =C18/C7 -> 0.12940798 | D19: =D18/D7 -> 0.36175381 | E19: =E18/E7 -> 0.48483065 | F19: =F18/F7 -> 0.82267232 | G19: =G18/G7 -> 0.85160658 | H19: =H18/H7 -> 0.83490954 | I19: =I18/I7 -> 0.76553364 | J19: =J18/J7 -> 0.67566116 | K19: =K18/K7 -> 0.68684762
B20: Interest income | C20: 468 | D20: 529 | E20: 496 | F20: ='FY26 Bridge'!E17 -> 724 | G20: =SUM(F34:F35)*Assumptions!G$13 -> 2079.3527 | H20: =SUM(G34:G35)*Assumptions!H$13 -> 2054.0827 | I20: =SUM(H34:H35)*Assumptions!I$13 -> 2036.5827 | J20: =SUM(I34:I35)*Assumptions!J$13 -> 2019.0827 | K20: =SUM(J34:J35)*Assumptions!K$13 -> 2001.5827
B21: Interest expense | C21: 388 | D21: 562 | E21: 477 | F21: ='FY26 Bridge'!E18 -> 106 | G21: =AVERAGE(F45,G45)*Assumptions!G$14 -> 268.05 | H21: =AVERAGE(G45,H45)*Assumptions!H$14 -> 237.5 | I21: =AVERAGE(H45,I45)*Assumptions!I$14 -> 212.5 | J21: =AVERAGE(I45,J45)*Assumptions!J$14 -> 187.5 | K21: =AVERAGE(J45,K45)*Assumptions!K$14 -> 162.5
B22: Other income / (expense) | C22: 7 | D22: -31 | E22: -135 | F22: ='FY26 Bridge'!E19 -> -559 | G22: =G7*Assumptions!G$15 -> -304.34324 | H22: =H7*Assumptions!H$15 -> -322.60383 | I22: =I7*Assumptions!I$15 -> -290.34345 | J22: =J7*Assumptions!J$15 -> -275.82628 | K22: =K7*Assumptions!K$15 -> -292.37586
B23: Income / (loss) before taxes | C23: =C15+C20-C21+C22 -> -5658 | D23: =D15+D20-D21+D22 -> 1240 | E23: =E15+E20-E21+E22 -> 9654 | F23: =F15+F20-F21+F22 -> 96788 | G23: =G15+G20-G21+G22 -> 118329.11 | H23: =H15+H20-H21+H22 -> 118873.38 | I23: =I15+I20-I21+I22 -> 92062.827 | J23: =J15+J20-J21+J22 -> 72512.067 | K23: =K15+K20-K21+K22 -> 80122.718
B24: Income tax expense | C24: 177 | D24: 451 | E24: 1124 | F24: ='FY26 Bridge'!E22 -> 14381.25 | G24: =MAX(0,G23*Assumptions!G$12) -> 17749.367 | H24: =MAX(0,H23*Assumptions!H$12) -> 17831.008 | I24: =MAX(0,I23*Assumptions!I$12) -> 13809.424 | J24: =MAX(0,J23*Assumptions!J$12) -> 10876.81 | K24: =MAX(0,K23*Assumptions!K$12) -> 12018.408
B25: Equity in income / (loss) of investees | C25: 2 | D25: -11 | E25: 9 | F25: =Assumptions!F$57 -> 13 | G25: =Assumptions!G$57 -> 0 | H25: =Assumptions!H$57 -> 0 | I25: =Assumptions!I$57 -> 0 | J25: =Assumptions!J$57 -> 0 | K25: =Assumptions!K$57 -> 0
B26: Net income / (loss) | C26: =C23-C24+C25 -> -5833 | D26: =D23-D24+D25 -> 778 | E26: =E23-E24+E25 -> 8539 | F26: =F23-F24+F25 -> 82419.75 | G26: =G23-G24+G25 -> 100579.75 | H26: =H23-H24+H25 -> 101042.38 | I26: =I23-I24+I25 -> 78253.403 | J26: =J23-J24+J25 -> 61635.257 | K26: =K23-K24+K25 -> 68104.31
B27: Diluted shares | C27: 1093 | D27: 1118 | E27: 1125 | F27: =Assumptions!F$33 -> 1150 | G27: =Assumptions!G$33 -> 1081.1122 | H27: =Assumptions!H$33 -> 1008.0331 | I27: =Assumptions!I$33 -> 940.75514 | J27: =Assumptions!J$33 -> 880.5376 | K27: =Assumptions!K$33 -> 816.28826
B28: Diluted EPS | C28: =C26/C27 -> -5.336688 | D28: =D26/D27 -> 0.69588551 | E28: =E26/E27 -> 7.5902222 | F28: =F26/F27 -> 71.669348 | G28: =G26/G27 -> 93.033584 | H28: =H26/H27 -> 100.23716 | I28: =I26/I27 -> 83.181479 | J28: =J26/J27 -> 69.997302 | K28: =K26/K27 -> 83.431692
B29: Free cash flow | C29: =C81 -> -5407 | D29: =D81 -> 436 | E29: =E81 -> 3673 | F29: =F81 -> 57752.276 | G29: =G81 -> 65575.568 | H29: =H81 -> 69677.426 | I29: =I81 -> 64309.054 | J29: =J81 -> 57840.198 | K29: =K81 -> 61732.639
B32: BALANCE SHEET
B34: Cash, cash equivalents and restricted cash | C34: 8656 | D34: 7052 | E34: 9646 | F34: =F79 -> 54251.716 | G34: =G79 -> 52601.211 | H34: =H79 -> 51735.999 | I34: =I79 -> 51881.207 | J34: =J79 -> 51671.551 | K34: =K79 -> 50840.559
B35: Marketable securities | C35: 1861 | D35: 2111 | E35: 2294 | F35: =F7*Assumptions!F$23 -> 5158.36 | G35: =G7*Assumptions!G$23 -> 6086.8648 | H35: =H7*Assumptions!H$23 -> 6452.0767 | I35: =I7*Assumptions!I$23 -> 5806.869 | J35: =J7*Assumptions!J$23 -> 5516.5256 | K35: =K7*Assumptions!K$23 -> 5847.5171
B36: Receivables | C36: 2443 | D36: 6615 | E36: 9265 | F36: =F7*Assumptions!F$18/365 -> 28264.986 | G36: =G7*Assumptions!G$18/365 -> 29183.598 | H36: =H7*Assumptions!H$18/365 -> 28724.999 | I36: =I7*Assumptions!I$18/365 -> 23863.845 | J36: =J7*Assumptions!J$18/365 -> 20781.432 | K36: =K7*Assumptions!K$18/365 -> 22028.318
B37: Inventories | C37: 8387 | D37: 8875 | E37: 8355 | F37: =F9*Assumptions!F$19/365 -> 8523.9562 | G37: =G9*Assumptions!G$19/365 -> 8630.0069 | H37: =H9*Assumptions!H$19/365 -> 10694.538 | I37: =I9*Assumptions!I$19/365 -> 13363.753 | J37: =J9*Assumptions!J$19/365 -> 16662.93 | K37: =K9*Assumptions!K$19/365 -> 16821.625
B38: Other current assets | C38: 820 | D38: 776 | E38: 914 | F38: =F7*Assumptions!F$21 -> 1289.59 | G38: =G7*Assumptions!G$21 -> 1521.7162 | H38: =H7*Assumptions!H$21 -> 1613.0192 | I38: =I7*Assumptions!I$21 -> 1451.7173 | J38: =J7*Assumptions!J$21 -> 1379.1314 | K38: =K7*Assumptions!K$21 -> 1461.8793
B39: Property, plant and equipment, net | C39: 37928 | D39: 39749 | E39: 46590 | F39: =E39+Assumptions!F$27-Assumptions!F$30-F17 -> 63841 | G39: =F39+Assumptions!G$27-Assumptions!G$30-G17 -> 96072.8 | H39: =G39+Assumptions!H$27-Assumptions!H$30-H17 -> 128779.7 | I39: =H39+Assumptions!I$27-Assumptions!I$30-I17 -> 148174.94 | J39: =I39+Assumptions!J$27-Assumptions!J$30-J17 -> 155948.7 | K39: =J39+Assumptions!K$27-Assumptions!K$30-K17 -> 162115.88
B40: Other long-term assets | C40: 4159 | D40: 4238 | E40: 5734 | F40: =F7*Assumptions!F$24 -> 6963.786 | G40: =G7*Assumptions!G$24 -> 7608.581 | H40: =H7*Assumptions!H$24 -> 8065.0959 | I40: =I7*Assumptions!I$24 -> 7258.5863 | J40: =J7*Assumptions!J$24 -> 6895.657 | K40: =K7*Assumptions!K$24 -> 7309.3964
B41: Total assets | C41: =SUM(C34:C40) -> 64254 | D41: =SUM(D34:D40) -> 69416 | E41: =SUM(E34:E40) -> 82798 | F41: =SUM(F34:F40) -> 168293.39 | G41: =SUM(G34:G40) -> 201704.78 | H41: =SUM(H34:H40) -> 236065.42 | I41: =SUM(I34:I40) -> 251800.92 | J41: =SUM(J34:J40) -> 258855.93 | K41: =SUM(K34:K40) -> 266425.18
B44: Accounts payable and accrued expenses | C44: 3958 | D44: 7299 | E44: 9649 | F44: =F9*Assumptions!F$20/365 -> 13973.699 | G44: =G9*Assumptions!G$20/365 -> 13507.837 | H44: =H9*Assumptions!H$20/365 -> 16041.807 | I44: =I9*Assumptions!I$20/365 -> 19091.076 | J44: =J9*Assumptions!J$20/365 -> 23010.713 | K44: =K9*Assumptions!K$20/365 -> 23229.862
B45: Debt | C45: 13330 | D45: 13397 | E45: 14577 | F45: =Assumptions!F$28 -> 5722 | G45: =Assumptions!G$28 -> 5000 | H45: =Assumptions!H$28 -> 4500 | I45: =Assumptions!I$28 -> 4000 | J45: =Assumptions!J$28 -> 3500 | K45: =Assumptions!K$28 -> 3000
B46: Other current liabilities | C46: 529 | D46: 1518 | E46: 1245 | F46: =F7*Assumptions!F$22 -> 3352.934 | G46: =G7*Assumptions!G$22 -> 3804.2905 | H46: =H7*Assumptions!H$22 -> 4032.5479 | I46: =I7*Assumptions!I$22 -> 3629.2931 | J46: =J7*Assumptions!J$22 -> 3447.8285 | K46: =K7*Assumptions!K$22 -> 3654.6982
B47: Other long-term liabilities | C47: 2317 | D47: 2071 | E47: 3162 | F47: =F7*Assumptions!F$25 -> 8769.212 | G47: =G7*Assumptions!G$25 -> 6847.7229 | H47: =H7*Assumptions!H$25 -> 6452.0767 | I47: =I7*Assumptions!I$25 -> 5081.0104 | J47: =J7*Assumptions!J$25 -> 4137.3942 | K47: =K7*Assumptions!K$25 -> 4385.6378
...

Sheet DCF
B2: Micron Technology (MU) — DCF Valuation
B3: The DCF values Micron using cash generated by operations after taxes, capital spending and working capital needs.
B5: Fiscal Year | C5: FY2027E | D5: FY2028E | E5: FY2029E | F5: FY2030E | G5: FY2031E
B6: Operating income | C6: =Statements!G15 -> 116822.15 | D6: =Statements!H15 -> 117379.41 | E6: =Statements!I15 -> 90529.088 | F6: =Statements!J15 -> 70956.31 | G6: =Statements!K15 -> 78576.011
B7: Tax rate | C7: =Assumptions!G$12 -> 0.15 | D7: =Assumptions!H$12 -> 0.15 | E7: =Assumptions!I$12 -> 0.15 | F7: =Assumptions!J$12 -> 0.15 | G7: =Assumptions!K$12 -> 0.15
B8: NOPAT | C8: =C6*(1-C7) -> 99298.83 | D8: =D6*(1-D7) -> 99772.494 | E8: =E6*(1-E7) -> 76949.725 | F8: =F6*(1-F7) -> 60312.864 | G8: =G6*(1-G7) -> 66789.609
B9: Depreciation and amortization | C9: =Statements!G17 -> 12768.2 | D9: =Statements!H17 -> 17293.104 | E9: =Statements!I17 -> 20604.751 | F9: =Statements!J17 -> 22226.242 | G9: =Statements!K17 -> 21832.818
B10: Capital expenditures | C10: =Statements!G67 -> -45000 | D10: =Statements!H67 -> -50000 | E10: =Statements!I67 -> -40000 | F10: =Statements!J67 -> -30000 | G10: =Statements!K67 -> -28000
B11: Change in working capital and other operating items | C11: =Statements!G65 -> -3837.5783 | D11: =Statements!H65 -> 212.83181 | E11: =Statements!I65 -> 4434.6979 | F11: =Statements!J65 -> 3013.3076 | G11: =Statements!K65 -> -1227.8048
B12: Unlevered free cash flow | C12: =SUM(C8:C11) -> 63229.451 | D12: =SUM(D8:D11) -> 67278.43 | E12: =SUM(E8:E11) -> 61989.174 | F12: =SUM(F8:F11) -> 55552.413 | G12: =SUM(G8:G11) -> 59394.623
B13: Discount period | C13: 0.5 | D13: 1.5 | E13: 2.5 | F13: 3.5 | G13: 4.5
B14: Discount factor | C14: =1/(1+$C$28)^C13 -> 0.94776751 | D14: =1/(1+$C$28)^D13 -> 0.85134472 | E14: =1/(1+$C$28)^E13 -> 0.76473168 | F14: =1/(1+$C$28)^F13 -> 0.68693036 | G14: =1/(1+$C$28)^G13 -> 0.6170443
B15: Present value of free cash flow | C15: =C12*C14 -> 59926.82 | D15: =D12*D14 -> 57277.137 | E15: =E12*E14 -> 47405.085 | F15: =F12*F14 -> 38160.639 | G15: =G12*G14 -> 36649.114
B16: Stock-based compensation is not added back to free cash flow (treated as a real expense).
B18: WACC CALCULATION
B19: Risk-free rate | C19: =Assumptions!C38 -> 0.0499
B20: Beta | C20: =Assumptions!C39 -> 1.5068655
B21: Equity risk premium | C21: =Assumptions!C40 -> 0.0423
B22: Cost of equity | C22: =C19+C20*C21 -> 0.11364041
B23: Equity value | C23: =Assumptions!C37*Assumptions!C45 -> 1062634.5
B24: Debt | C24: =Statements!F45 -> 5722
B25: Equity weight | C25: =C23/SUM(C23:C24) -> 0.99464411
B26: Debt weight | C26: =C24/SUM(C23:C24) -> 0.0053558901
B27: After-tax cost of debt | C27: =Assumptions!C41*(1-Assumptions!C42) -> 0.0425
B28: WACC | C28: =C25*C22+C26*C27 -> 0.11325939
B30: DCF VALUE
B31: Terminal growth rate | C31: =Assumptions!C43 -> 0.03
B32: Terminal-year free cash flow | C32: =G12*(1+C31) -> 61176.462
B33: Terminal value | C33: =C32/(C28-C31) -> 734769.5
B34: Present value of terminal value | C34: =C33*G14 -> 453385.33
B35: Present value of forecast free cash flow | C35: =SUM(C15:G15) -> 239418.79
B36: Enterprise value | C36: =SUM(C34:C35) -> 692804.13
B37: Less: net debt / (cash), FY2026E year-end | C37: =Assumptions!C44 -> -53688.076
B38: Equity value | C38: =C36-C37 -> 746492.2
B39: Diluted shares (millions) | C39: =Assumptions!C45 -> 1150
B40: Implied value per share | C40: =C38/C39 -> 649.12366
B41: Current share price | C41: =Assumptions!C37 -> 924.03
B42: Implied upside / (downside) | C42: =C40/C41-1 -> -0.29750803
B43: Terminal value as % of enterprise value | C43: =C34/C36 -> 0.65442066
B44: Implied terminal EV / FY2031E EBITDA | C44: =C33/Statements!K18 -> 7.3177778
...

Sheet Checks
B2: Micron Technology (MU) — Model Checks
B3: All checks should equal zero
B5: Fiscal Year | C5: FY2023A | D5: FY2024A | E5: FY2025A | F5: FY2026E | G5: FY2027E | H5: FY2028E | I5: FY2029E | J5: FY2030E | K5: FY2031E
B6: Balance sheet check | C6: =Statements!C52 -> 0 | D6: =Statements!D52 -> 0 | E6: =Statements!E52 -> 0 | F6: =Statements!F52 -> 0 | G6: =Statements!G52 -> 0 | H6: =Statements!H52 -> 0 | I6: =Statements!I52 -> 0 | J6: =Statements!J52 -> 0 | K6: =Statements!K52 -> 0
B7: Cash-flow reconciliation check | C7: =Statements!C80 -> 0 | D7: =Statements!D80 -> 0 | E7: =Statements!E80 -> 0 | F7: =Statements!F80 -> 0 | G7: =Statements!G80 -> 0 | H7: =Statements!H80 -> 0 | I7: =Statements!I80 -> 0 | J7: =Statements!J80 -> 0 | K7: =Statements!K80 -> 0
B8: PP&E roll-forward check | F8: =Statements!F39-(Statements!E39+Assumptions!F$27-Assumptions!F$30-Statements!F17) -> 0 | G8: =Statements!G39-(Statements!F39+Assumptions!G$27-Assumptions!G$30-Statements!G17) -> 0 | H8: =Statements!H39-(Statements!G39+Assumptions!H$27-Assumptions!H$30-Statements!H17) -> 0 | I8: =Statements!I39-(Statements!H39+Assumptions!I$27-Assumptions!I$30-Statements!I17) -> 0 | J8: =Statements!J39-(Statements!I39+Assumptions!J$27-Assumptions!J$30-Statements!J17) -> 0 | K8: =Statements!K39-(Statements!J39+Assumptions!K$27-Assumptions!K$30-Statements!K17) -> 0
B9: Debt roll-forward check | F9: =Statements!F45-(Statements!E45+Statements!F71) -> 0 | G9: =Statements!G45-(Statements!F45+Statements!G71) -> 0 | H9: =Statements!H45-(Statements!G45+Statements!H71) -> 0 | I9: =Statements!I45-(Statements!H45+Statements!I71) -> 0 | J9: =Statements!J45-(Statements!I45+Statements!J71) -> 0 | K9: =Statements!K45-(Statements!J45+Statements!K71) -> 0
B10: Equity roll-forward check | F10: =Statements!F50-(Statements!E50+Statements!F26+Statements!F64-Assumptions!F$31-Assumptions!F$32+Statements!F74+Statements!F76) -> 0 | G10: =Statements!G50-(Statements!F50+Statements!G26+Statements!G64-Assumptions!G$31-Assumptions!G$32+Statements!G74+Statements!G76) -> 0 | H10: =Statements!H50-(Statements!G50+Statements!H26+Statements!H64-Assumptions!H$31-Assumptions!H$32+Statements!H74+Statements!H76) -> 0 | I10: =Statements!I50-(Statements!H50+Statements!I26+Statements!I64-Assumptions!I$31-Assumptions!I$32+Statements!I74+Statements!I76) -> 0 | J10: =Statements!J50-(Statements!I50+Statements!J26+Statements!J64-Assumptions!J$31-Assumptions!J$32+Statements!J74+Statements!J76) -> 0 | K10: =Statements!K50-(Statements!J50+Statements!K26+Statements!K64-Assumptions!K$31-Assumptions!K$32+Statements!K74+Statements!K76) -> 0
B11: FY26 Bridge: 9M net income vs. reported | F11: ='FY26 Bridge'!C38 -> 0
B13: DCF enterprise-value check | C13: =DCF!C36-SUM(DCF!C34:C35) -> 0
B14: WACC sensitivity center vs. DCF value | C14: =DCF!E51-DCF!C40 -> 0
B15: Beta sensitivity center vs. DCF value | C15: =DCF!F59-DCF!C40 -> 0
B16: Scenario table matches live model (active case) | C16: =IF(Assumptions!C48=1,DCF!C40-INDEX(Summary!C21:C23,Assumptions!C62),DCF!C40-INDEX(Summary!E21:E23,Assumptions!C62)) -> 0.0036554017
B17: Tolerance | C17: 0.1
B18: Status | C18: =IF(MAX(MAX(C6:K11),-MIN(C6:K11),ABS(C13),ABS(C14),ABS(C15),ABS(C16))<=C17,"All checks within tolerance","Review failed checks") -> All checks within tolerance
B19: Interpretation | C19: All formula links reconcile when the checks above are zero. If the scenario check fails after changing inputs, update the Summary scenario table.

Sheet Sources
B2: Micron Technology (MU) — Sources and Simplifications
B5: Source | C5: Period | D5: Used for | E5: Section | F5: URL | G5: Notes
B6: Micron FY2025 Form 10-K | C6: FY2023–FY2025 | D6: Historical statements | E6: Item 8 | F6: https://s25.q4cdn.com/621799436/files/doc_financials/2025/ar/2025-Form-10-K.pdf | G6: Filed October 3, 2025
B7: Micron FY2024 Form 10-K | C7: FY2023 | D7: Prior-year balance sheet | E7: Item 8 | F7: https://s25.q4cdn.com/621799436/files/doc_financials/2024/ar/2024-10K.pdf | G7: Filed October 4, 2024
B8: Micron Q3 FY2026 Form 10-Q | C8: Nine months ended May 28, 2026 | D8: Q3 FY2026 debt and net cash | E8: Part I, Item 1 | F8: https://s25.q4cdn.com/621799436/files/doc_financials/2026/q3/0000723125-26-000015.pdf | G8: Filed June 25, 2026
B9: Micron Q3 FY2026 earnings release (Exhibit 99.1) | C9: 9M FY2026; Q4 FY2026 outlook | D9: FY26 Bridge: 9M actuals; Q4 revenue, margin, opex, EPS, SBC and share-count guidance | E9: Financial tables; outlook | F9: https://www.sec.gov/Archives/edgar/data/723125/000072312526000013/a2026q3ex991-pressrelease.htm | G9: Published June 24, 2026
B10: Micron Q3 FY2026 earnings deck | C10: Q4 FY2026 outlook | D10: Capital-spending guidance (~$10B Q4, ~$27B FY2026) | E10: Outlook slides | F10: https://s25.q4cdn.com/621799436/files/doc_financials/2026/q3/Micron_Q3_26_Earnings_Deck.pdf | G10: Published June 24, 2026
B11: Micron Q3 FY2026 prepared remarks | C11: FY2027 commentary | D11: FY2027 capex and opex direction; capital return approach | E11: Outlook | F11: https://investors.micron.com/static-files/631b1a32-5537-46ae-8f40-82e42fc79dfe | G11: Published June 24, 2026
B12: Yahoo Finance / Nasdaq market data | C12: September 14, 2026 | D12: Share price ($924.03 close); 5-year monthly beta (2.22) | E12: n.a. | F12: https://finance.yahoo.com/quote/MU/ | G12: Close on 9/14/2026
B13: Trading Economics / FRED (DGS10) | C13: September 14, 2026 | D13: Risk-free rate: 10-year Treasury (~4.99%) | E13: n.a. | F13: https://fred.stlouisfed.org/series/dgs10 | G13: Close on 9/14/2026
B14: Damodaran — Implied equity risk premium | C14: January 2026 | D14: Equity risk premium (4.23%) | E14: n.a. | F14: https://pages.stern.nyu.edu/~adamodar/New_Home_Page/datafile/histimpl.html | G14: Implied premium at the start of 2026
B15: Damodaran — Betas by Sector (US) | C15: January 2026 | D15: Semiconductor unlevered beta, cash-corrected (1.50) | E15: n.a. | F15: https://pages.stern.nyu.edu/~adamodar/New_Home_Page/datafile/Betas.html | G15: Relevered on the Assumptions tab
B18: SIMPLIFICATIONS
B19: Revenue | C19: Forecast as one company wide total rather than separate DRAM and NAND schedules. Bull and bear cases change only revenue growth and gross margin.
B20: FY2026 estimate | C20: Built on the FY26 Bridge tab from nine month actuals plus Q4 guidance; Q4 items without guidance are labeled estimates. FY2026 results are scheduled for release on September 30, 2026.
B21: Working capital | C21: Receivables, inventory and payables use days (DSO, DIO, DPO) on a 365 day basis; other items use percentages of revenue.
B22: PP&E | C22: Beginning PP&E plus capital expenditures, less government incentives and depreciation.
B23: Debt and equity | C23: Direct year end debt and dividend inputs. Buybacks equal a payout share of free cash flow less dividends. Diluted shares fall with buybacks and rise with stock based compensation, both at an assumed price. Other financing and FX flows are routed through equity.
B24: DCF | C24: Mid year convention, one WACC, Gordon Growth terminal value. Stock-based compensation is not added back. Operating cash flow adjustments match the cash flow statement.
B25: Net cash | C25: Uses FY2026E year end net cash. Customer deposits under Strategic Customer Agreements are recorded in financing and are expected to be returned to customers later. The model does not deduct them from net cash.
